Exception on /api/locales [GET]
Traceback (most recent call last):
  File "/home/vagrant/recurso-app/flask-app/web/venv/local/lib/python2.7/site-packages/flask/app.py", line 2447, in wsgi_app
    response = self.full_dispatch_request()
  File "/home/vagrant/recurso-app/flask-app/web/venv/local/lib/python2.7/site-packages/flask/app.py", line 1945, in full_dispatch_request
    self.try_trigger_before_first_request_functions()
  File "/home/vagrant/recurso-app/flask-app/web/venv/local/lib/python2.7/site-packages/flask/app.py", line 1993, in try_trigger_before_first_request_functions
    func()
  File "/home/vagrant/recurso-app/flask-app/web/app.py", line 25, in setup_logging
    app.logger.setLevel(logging.INFO)
NameError: global name 'logging' is not defined
Exception on /api/recursos [GET]
Traceback (most recent call last):
  File "/home/vagrant/recurso-app/flask-app/web/venv/local/lib/python2.7/site-packages/flask/app.py", line 2447, in wsgi_app
    response = self.full_dispatch_request()
  File "/home/vagrant/recurso-app/flask-app/web/venv/local/lib/python2.7/site-packages/flask/app.py", line 1952, in full_dispatch_request
    rv = self.handle_user_exception(e)
  File "/home/vagrant/recurso-app/flask-app/web/venv/local/lib/python2.7/site-packages/flask_cors/extension.py", line 165, in wrapped_function
    return cors_after_request(app.make_response(f(*args, **kwargs)))
  File "/home/vagrant/recurso-app/flask-app/web/venv/local/lib/python2.7/site-packages/flask/app.py", line 1821, in handle_user_exception
    reraise(exc_type, exc_value, tb)
  File "/home/vagrant/recurso-app/flask-app/web/venv/local/lib/python2.7/site-packages/flask/app.py", line 1950, in full_dispatch_request
    rv = self.dispatch_request()
  File "/home/vagrant/recurso-app/flask-app/web/venv/local/lib/python2.7/site-packages/flask/app.py", line 1936, in dispatch_request
    return self.view_functions[rule.endpoint](**req.view_args)
  File "/home/vagrant/recurso-app/flask-app/web/app.py", line 82, in list_of_recursos
    list_of_recursos = models.storage.get_list(Recurso)
  File "/home/vagrant/recurso-app/flask-app/models/engine/db_storage.py", line 74, in get_list
    for instance in self.__session.query(Recurso):
  File "/home/vagrant/recurso-app/flask-app/web/venv/local/lib/python2.7/site-packages/sqlalchemy/orm/query.py", line 2887, in __iter__
    return self._iter().__iter__()
  File "/home/vagrant/recurso-app/flask-app/web/venv/local/lib/python2.7/site-packages/sqlalchemy/orm/query.py", line 2897, in _iter
    execution_options={"_sa_orm_load_options": self.load_options},
  File "/home/vagrant/recurso-app/flask-app/web/venv/local/lib/python2.7/site-packages/sqlalchemy/orm/session.py", line 1692, in execute
    result = conn._execute_20(statement, params or {}, execution_options)
  File "/home/vagrant/recurso-app/flask-app/web/venv/local/lib/python2.7/site-packages/sqlalchemy/engine/base.py", line 1614, in _execute_20
    return meth(self, args_10style, kwargs_10style, execution_options)
  File "/home/vagrant/recurso-app/flask-app/web/venv/local/lib/python2.7/site-packages/sqlalchemy/sql/elements.py", line 326, in _execute_on_connection
    self, multiparams, params, execution_options
  File "/home/vagrant/recurso-app/flask-app/web/venv/local/lib/python2.7/site-packages/sqlalchemy/engine/base.py", line 1491, in _execute_clauseelement
    cache_hit=cache_hit,
  File "/home/vagrant/recurso-app/flask-app/web/venv/local/lib/python2.7/site-packages/sqlalchemy/engine/base.py", line 1846, in _execute_context
    e, statement, parameters, cursor, context
  File "/home/vagrant/recurso-app/flask-app/web/venv/local/lib/python2.7/site-packages/sqlalchemy/engine/base.py", line 2027, in _handle_dbapi_exception
    sqlalchemy_exception, with_traceback=exc_info[2], from_=e
  File "/home/vagrant/recurso-app/flask-app/web/venv/local/lib/python2.7/site-packages/sqlalchemy/engine/base.py", line 1803, in _execute_context
    cursor, statement, parameters, context
  File "/home/vagrant/recurso-app/flask-app/web/venv/local/lib/python2.7/site-packages/sqlalchemy/engine/default.py", line 732, in do_execute
    cursor.execute(statement, parameters)
  File "/home/vagrant/recurso-app/flask-app/web/venv/local/lib/python2.7/site-packages/MySQLdb/cursors.py", line 205, in execute
    self.errorhandler(self, exc, value)
  File "/home/vagrant/recurso-app/flask-app/web/venv/local/lib/python2.7/site-packages/MySQLdb/connections.py", line 36, in defaulterrorhandler
    raise errorclass, errorvalue
OperationalError: (_mysql_exceptions.OperationalError) (2006, 'MySQL server has gone away')
[SQL: SELECT recurso.recurso_id AS recurso_recurso_id, recurso.nombre AS recurso_nombre, recurso.apellido AS recurso_apellido 
FROM recurso]
(Background on this error at: https://sqlalche.me/e/14/e3q8)
